Workbook

Sheet Protocol
A1: Item | B1: Value
A2: Search date | B2: 2026-10-27
A3: Search tool | B3: Claude WebSearch (web index; returns top ~10 results per query)
A4: Queries run | B4: =COUNTA('Search Log'!A2:A25) -> 24
A5: Result entries returned (sum) | B5: =SUM('Search Log'!E2:E25) -> 194
A6: Distinct records screened (rows in Screening) | B6: =COUNTA(Screening!A2:A500) -> 53
A7: Included | B7: =COUNTIF(Screening!I2:I500,"Include") -> 38
A8: of which academic | B8: =COUNTIFS(Screening!I2:I500,"Include",Screening!H2:H500,"Primary (academic)") -> 29
A9: of which grey literature | B9: =COUNTIFS(Screening!I2:I500,"Include",Screening!H2:H500,"Grey literature") -> 9
A10: Excluded | B10: =COUNTIF(Screening!I2:I500,"Exclude") -> 13
A11: Pending verification | B11: =COUNTIF(Screening!I2:I500,"Pending verification") -> 2
A12: Inclusion criterion | B12: Proposes, evaluates or measures an attack, defense, benchmark or incident in which an AI code model or coding agent produces, consumes or acts on software-supply-chain artifacts.
A13: Exclusions | B13: (i) code quality/productivity with no security analysis; (ii) general LLM jailbreak/injection work not applied to coding; (iii) model-weight or LLM-framework supply chain; (iv) duplicates. Secondary studies are kept as related work only.
A14: Screener | B14: Single screener (Claude) on titles, abstracts and retrieved pages, with every decision reviewed by the author. Screening was not double-screened. Coding reliability: a 17-paper sample was coded by an independent human coder (16/17 agreement with the first coding, kappa = 0.93; see Double coding sheet).
A15: Limitation 1 | B15: WebSearch returns ~10 web results per query and does not query IEEE Xplore, ACM DL or Scopus databases directly; domain filters were not always honored. This is a targeted search, not an exhaustive database search.
A16: Limitation 2 | B16: Five queries (Q05, Q13, Q16, Q17, plus Q10) were known-item or snowball searches for specific papers; report them as such.
A17: Verification pass | B17: 27 Oct 2026: bibliographic details checked against primary pages for 16 records; corrections recorded in the Verification note column.
A18: Limitation 3 | B18: Records marked 'prior scoping' came from earlier searches in this conversation, before the logged protocol began. Re-run a logged query for them or report them as scoping sources.
A19: Limitation 4 | B19: Bibliographic fields marked 'confirm' or 'not retrieved' must be checked against the publisher page before citation.
A20: Limitation 5 | B20: Threat-class labels are provisional (single coder) and must be double-coded on a 20% sample before reporting kappa.
A21: Expanded re-run (2026-10-27) | B21: D09 IEEE (465) and D10 ACM (210) with the expanded AI-term group and security clause; plus delta runs D11 ACM (30) and D12 IEEE (61) for 'LMs for code' variants; 165 records screened at abstract stage; see 'Abstract Screening'. Recall on known papers rose from 4/9 to 7/9 (SVEN and the ISSTA 2026 model-editing paper stay known-item additions). Protocol amendment: T7 scoping rule (see note under 'Abstract Screening').
A22: Final coded corpus (web phase + database re-run) | B22: =COUNTA(Coding!A2:A200)-COUNTIF(Coding!A2:A200,"Legend*") -> 96
A23: of which academic | B23: =COUNTIF(Coding!C2:C200,"Academic") -> 87
A24: of which peer reviewed | B24: =COUNTIFS(Coding!C2:C200,"Academic",Coding!D2:D200,"Y") -> 75
A25: of which grey literature | B25: =COUNTIF(Coding!C2:C200,"Grey") -> 9
A26: T7 studies characterized in aggregate (scoping rule not met) | B26: =COUNTIF('Abstract Screening'!K2:K300,"T7 aggregate*") -> 50
A27: Coded sources still needing a full-text check | B27: =COUNTIF(Coding!AC2:AC200,"Y") -> 82

Sheet Summary
A1: Metric | B1: Academic (peer-reviewed + preprints) | C1: Grey literature | D1: Note
A2: Sources covering T1 Package hallucination | B2: =SUMIFS(Coding!$F$2:$F$97,Coding!$C$2:$C$97,"Academic") -> 6 | C2: =SUMIFS(Coding!$F$2:$F$97,Coding!$C$2:$C$97,"Grey") -> 0 | D2: A source can cover several classes
A3: Sources covering T2 Malicious/vulnerable dependency intake | B3: =SUMIFS(Coding!$G$2:$G$97,Coding!$C$2:$C$97,"Academic") -> 9 | C3: =SUMIFS(Coding!$G$2:$G$97,Coding!$C$2:$C$97,"Grey") -> 1 | D3: A source can cover several classes
A4: Sources covering T3 Repository prompt injection | B4: =SUMIFS(Coding!$H$2:$H$97,Coding!$C$2:$C$97,"Academic") -> 16 | C4: =SUMIFS(Coding!$H$2:$H$97,Coding!$C$2:$C$97,"Grey") -> 5 | D4: A source can cover several classes
A5: Sources covering T4 Forge-metadata injection | B5: =SUMIFS(Coding!$I$2:$I$97,Coding!$C$2:$C$97,"Academic") -> 2 | C5: =SUMIFS(Coding!$I$2:$I$97,Coding!$C$2:$C$97,"Grey") -> 2 | D5: A source can cover several classes
A6: Sources covering T5 Tool/MCP/skill compromise | B6: =SUMIFS(Coding!$J$2:$J$97,Coding!$C$2:$C$97,"Academic") -> 7 | C6: =SUMIFS(Coding!$J$2:$J$97,Coding!$C$2:$C$97,"Grey") -> 1 | D6: A source can cover several classes
A7: Sources covering T6 Secret leakage | B7: =SUMIFS(Coding!$K$2:$K$97,Coding!$C$2:$C$97,"Academic") -> 15 | C7: =SUMIFS(Coding!$K$2:$K$97,Coding!$C$2:$C$97,"Grey") -> 4 | D7: A source can cover several classes
A8: Sources covering T7 Insecure code generation | B8: =SUMIFS(Coding!$L$2:$L$97,Coding!$C$2:$C$97,"Academic") -> 40 | C8: =SUMIFS(Coding!$L$2:$L$97,Coding!$C$2:$C$97,"Grey") -> 1 | D8: A source can cover several classes
A9: Sources covering T8 Training-data poisoning | B9: =SUMIFS(Coding!$M$2:$M$97,Coding!$C$2:$C$97,"Academic") -> 16 | C9: =SUMIFS(Coding!$M$2:$M$97,Coding!$C$2:$C$97,"Grey") -> 0 | D9: A source can cover several classes
A10: Attack papers | B10: =SUMIFS(Coding!$N$2:$N$97,Coding!$C$2:$C$97,"Academic") -> 21 | C10: =SUMIFS(Coding!$N$2:$N$97,Coding!$C$2:$C$97,"Grey") -> 7
A11: Measurement studies | B11: =SUMIFS(Coding!$O$2:$O$97,Coding!$C$2:$C$97,"Academic") -> 32 | C11: =SUMIFS(Coding!$O$2:$O$97,Coding!$C$2:$C$97,"Grey") -> 2
A12: Benchmarks | B12: =SUMIFS(Coding!$P$2:$P$97,Coding!$C$2:$C$97,"Academic") -> 15 | C12: =SUMIFS(Coding!$P$2:$P$97,Coding!$C$2:$C$97,"Grey") -> 0
A13: Defense papers | B13: =SUMIFS(Coding!$Q$2:$Q$97,Coding!$C$2:$C$97,"Academic") -> 38 | C13: =SUMIFS(Coding!$Q$2:$Q$97,Coding!$C$2:$C$97,"Grey") -> 0
A14: User studies | B14: =SUMIFS(Coding!$R$2:$R$97,Coding!$C$2:$C$97,"Academic") -> 6 | C14: =SUMIFS(Coding!$R$2:$R$97,Coding!$C$2:$C$97,"Grey") -> 0
A15: Total sources | B15: =COUNTIF(Coding!$C$2:$C$97,"Academic") -> 87 | C15: =COUNTIF(Coding!$C$2:$C$97,"Grey") -> 9
A16: Peer reviewed | B16: =COUNTIFS(Coding!$C$2:$C$97,"Academic",Coding!$D$2:$D$97,"Y") -> 75
A17: Evaluated on a tool-using agent (L3+) | B17: =COUNTIFS(Coding!$C$2:$C$97,"Academic",Coding!$V$2:$V$97,"Y") -> 18 | C17: =COUNTIFS(Coding!$C$2:$C$97,"Grey",Coding!$V$2:$V$97,"Y") -> 7
A18: Share of academic sources evaluated on an agent | B18: =B17/B15 -> 0.20689655
A19: Defense papers evaluated on an agent | B19: =COUNTIFS(Coding!$C$2:$C$97,"Academic",Coding!$Q$2:$Q$97,1,Coding!$V$2:$V$97,"Y") -> 7
A20: Defense papers at maturity E1 | B20: =COUNTIFS(Coding!$C$2:$C$97,"Academic",Coding!$X$2:$X$97,"E1") -> 30
A21: Defense papers at maturity E2 | B21: =COUNTIFS(Coding!$C$2:$C$97,"Academic",Coding!$X$2:$X$97,"E2") -> 7
A22: Defense papers at maturity E3 | B22: =COUNTIFS(Coding!$C$2:$C$97,"Academic",Coding!$X$2:$X$97,"E3") -> 0
A23: Defenses enforced at S2 generation | B23: =COUNTIFS(Coding!$C$2:$C$97,"Academic",Coding!$W$2:$W$97,"S2*") -> 14 | D23: Wildcard match on enforcement point
A24: Defenses enforced at TB2 action plane | B24: =COUNTIFS(Coding!$C$2:$C$97,"Academic",Coding!$W$2:$W$97,"*TB2*") -> 4
A25: Defenses enforced at S3 dependency intake | B25: =COUNTIFS(Coding!$C$2:$C$97,"Academic",Coding!$W$2:$W$97,"*S3*") -> 3
A26: Papers with utility measured | B26: =COUNTIFS(Coding!$C$2:$C$97,"Academic",Coding!$Y$2:$Y$97,"Y") -> 15
A27: Papers with adaptive attacker | B27: =COUNTIFS(Coding!$C$2:$C$97,"Academic",Coding!$Z$2:$Z$97,"Y") -> 7
A28: Papers releasing artifacts (stated) | B28: =COUNTIFS(Coding!$C$2:$C$97,"Academic",Coding!$AA$2:$AA$97,"Y") -> 8

Sheet Search Log
A1: Query ID | B1: Query string | C1: Domain filter | D1: Date run | E1: Results returned | F1: Candidate records surfaced
A2: Q01 | B2: package hallucination code generation LLM | C2: arxiv.org | D2: 2026-10-27 | E2: 7 | F2: Spracklen et al. (USENIX Sec 2025)
A3: Q02 | B3: prompt injection coding agent | C3: arxiv.org | D3: 2026-10-27 | E3: 7 | F3: QueryIPI; SkillJect
A4: Q03 | B4: security of code generated by Copilot vulnerabilities | C4: arxiv.org | D4: 2026-10-27 | E4: 9 | F4: Pearce et al.; Fu et al. (Copilot in GitHub projects)
A5: Q04 | B5: poisoning backdoor neural code completion model | C5: arxiv.org | D5: 2026-10-27 | E5: 9 | F5: CodeBreaker; Schuster et al.
A6: Q05 | B6: TrojanPuzzle covertly poisoning code-suggestion models | C6: arxiv.org, ieeexplore.ieee.org, computer.org | D6: 2026-10-27 | E6: 7 | F6: TrojanPuzzle (known-item search)
A7: Q06 | B7: MCP tool poisoning attack LLM agents | C7: arxiv.org | D7: 2026-10-27 | E7: 7 | F7: MCPTox; OWASP MCP Tool Poisoning (grey)
A8: Q07 | B8: hardcoded secrets credentials leakage code LLM generated | C8: arxiv.org | D8: 2026-10-27 | E8: 7 | F8: No primary paper; vendor blogs pointed to Huang et al. (see Q09)
A9: Q08 | B9: security benchmark coding agents unsafe actions | C9: arxiv.org | D9: 2026-10-27 | E9: 7 | F9: RedCode; SABER; aggregator mentions (IssueTrojanBench, AgentS4D, VulnGym)
A10: Q09 | B10: neural code completion tools memorize hard-coded credentials | C10: arxiv.org, dl.acm.org | D10: 2026-10-27 | E10: 7 | F10: Huang et al. (FSE 2024)
A11: Q10 | B11: IssueTrojanBench indirect prompt injection coding agent issues | C11: none | D11: 2026-10-27 | E11: 7 | F11: IssueTrojanBench (secondary summaries only)
A12: Q11 | B12: secure code generation LLM defense hardening | C12: arxiv.org | D12: 2026-10-27 | E12: 9 | F12: SVEN; DeepGuard; CoSec; constrained decoding; model editing; RvB
A13: Q12 | B13: defense prompt injection LLM agents structured queries capabilities | C13: arxiv.org | D13: 2026-10-27 | E13: 7 | F13: StruQ; ChatInject; AttackEval
... A25: Q24 | B25: systematic literature review security AI code generation LLM | C25: arxiv.org | D25: 2026-10-27 | E25: 10 | F25: Two prior SLRs (related work)
D26: Total | E26: =SUM(E2:E25) -> 194

Sheet Database Search
A1: Run ID | B1: Database | C1: Query | D1: Fields and years | E1: Hits | F1: Note
A2: D01 | B2: IEEE Xplore | C2: "coding agent" AND ("supply chain" OR dependency OR package OR "prompt injection" OR secret OR credential OR vulnerability OR poisoning OR backdoor) | D2: All metadata; 2021-2026 | E2: 9 | F2: Full string hung the IEEE results page twice; split into six slices, one per AI-coding term
A3: D02 | B3: IEEE Xplore | C3: "code LLM" AND ("supply chain" OR dependency OR package OR "prompt injection" OR secret OR credential OR vulnerability OR poisoning OR backdoor) | D3: All metadata; 2021-2026 | E3: 6
A4: D03 | B4: IEEE Xplore | C4: "code assistant" AND ("supply chain" OR dependency OR package OR "prompt injection" OR secret OR credential OR vulnerability OR poisoning OR backdoor) | D4: All metadata; 2021-2026 | E4: 4
A5: D04 | B5: IEEE Xplore | C5: "code generation model" AND ("supply chain" OR dependency OR package OR "prompt injection" OR secret OR credential OR vulnerability OR poisoning OR backdoor) | D5: All metadata; 2021-2026 | E5: 22 | F5: Many model-based-design (Simulink) false positives
A6: D05 | B6: IEEE Xplore | C6: "vibe coding" AND ("supply chain" OR dependency OR package OR "prompt injection" OR secret OR credential OR vulnerability OR poisoning OR backdoor) | D6: All metadata; 2021-2026 | E6: 11
A7: D06 | B7: IEEE Xplore | C7: Copilot AND ("supply chain" OR dependency OR package OR "prompt injection" OR secret OR credential OR vulnerability OR poisoning OR backdoor) | D7: All metadata; 2021-2026 | E7: 134 | F7: Two pages; many non-coding 'copilot' products
A8: D07 | B8: ACM DL | C8: Full §3 string (all six AI terms OR-ed) AND security clause | D8: All fields incl. full text; 2021-2026 | E8: 3621 | F8: Not screened: full-text matching is not comparable to IEEE metadata search
A9: D08 | B9: ACM DL | C9: Abstract:(six AI terms) AND Abstract:(security clause) | D9: Abstract only; 2021-2026 | E9: 70 | F9: Screened run for ACM
B11: IEEE hits, six slices (sum) | E11: =SUM(E2:E7) -> 186
B12: IEEE within-database duplicates across slices | E12: 4 | F12: Same paper returned by two slices (counted by title)
B13: IEEE unique | E13: =E11-E12 -> 182
B14: ACM screened run (D08) | E14: =E9 -> 70
B15: Duplicates between IEEE and ACM | E15: 5 | F15: Counted by title
B16: Unique records across both databases | E16: =E13+E14-E15 -> 247
B17: Search date | C17: 2026-10-27 (run in the user's Chrome; not signed in to either site)
A19: Expanded re-run (supersedes D01-D08 for screening)
A20: D09 | B20: IEEE Xplore | C20: ("code LLM" OR "coding agent" OR "code assistant" OR "code assistants" OR "code generation model" OR Copilot OR "vibe coding" OR "code completion" OR "LLM-generated code" OR "AI generated code" OR "language models for code") AND ("supply chain" OR dependency OR package OR "prompt injection" OR secret OR credential OR vulnerability OR poisoning OR backdoor OR security OR secure OR insecure) | D20: All metadata; 2021-2026; via the IEEE search endpoint used by the results page (100 records x 5 pages) | E20: 465 | F20: Full expanded string in one query; the results page itself hung on this string, the endpoint did not
A21: D10 | B21: ACM DL | C21: Abstract:("code LLM" OR "coding agent" OR "code assistant" OR "code assistants" OR "code generation model" OR Copilot OR "vibe coding" OR "code completion" OR "LLM-generated code" OR "AI generated code" OR "language models for code") AND Abstract:("supply chain" OR dependency OR package OR "prompt injection" OR secret OR credential OR vulnerability OR poisoning OR backdoor OR security OR secure OR insecure) | D21: Abstract only; 2021-2026; 50 per page x 5 pages | E21: 210 | F21: ACM accepts the hyphenated 'AI-generated code'
A22: D11 | B22: ACM DL | C22: Abstract:("LMs for code" OR "large language models for code" OR "language models of code" OR "code language model" OR "code language models") AND Abstract:("supply chain" OR dependency OR package OR "prompt injection" OR secret OR credential OR vulnerability OR poisoning OR backdoor OR security OR secure OR insecure) | D22: Abstract only; 2021-2026 | E22: 30 | F22: Delta run to close the recall gap (SVEN); 3 new includes; SVEN still not retrieved (its abstract says 'large LMs')
A23: D12 | B23: IEEE Xplore | C23: ("LMs for code" OR "large language models for code" OR "language models of code" OR "code language model" OR "code language models") AND ("supply chain" OR dependency OR package OR "prompt injection" OR secret OR credential OR vulnerability OR poisoning OR backdoor OR security OR secure OR insecure) | D23: All metadata; 2021-2026; search endpoint | E23: 61 | F23: Delta run; 6 new includes (one shared with D11)
B24: Records screened (title + abstract) in D09-D12 | E24: =E20+E21+E22+E23 -> 766
B25: Cross-database duplicates among abstract-screened records | E25: =COUNTIF('Abstract Screening'!G:G,"Duplicate (other database)") -> 6 | F25: Matched by title/DOI. Duplicates among records excluded at title stage were not counted
B26: Search date | C26: 2026-10-27 (user's Chrome, not signed in)

Sheet DB Candidates
A1: ID | B1: Title | C1: Venue | D1: Found by | E1: Title-stage decision | F1: Provisional class / note
A2: I01 | B2: Static Analysis of Vulnerabilities That AI-Based Code Assistants May Introduce | C2: ISADES 2026 | D2: D01, D05 | E2: Include for abstract screening | F2: T7
A3: I02 | B3: ShadowCode: Toward (Automatic) External Prompt Injection Attack Against Code LLMs | C3: IEEE TDSC 2026 | D3: D02 | E3: Include for abstract screening | F3: T3, T5
A4: I03 | B4: Decoding Secret Memorization in Code LLMs Through Token-Level Characterization | C4: ICSE 2025 | D4: D02, D08 | E4: Include for abstract screening | F4: T6
A5: I04 | B5: PwnPilot: Reflections on Trusting Trust in the Age of LLMs and AI Code Assistants | C5: CSCE 2023 | D5: D03, D06 | E5: Include for abstract screening | F5: T8
A6: I05 | B6: A Disguised Wolf Is More Harmful Than a Toothless Tiger: Adaptive and Malicious Code Injection Backdoor Attack | C6: IEEE TIFS 2025 | D6: D04 | E6: Include for abstract screening | F6: T8
A7: I06 | B7: Towards Secure Code Generation With LLMs: A Study on Common Weakness Enumeration | C7: IEEE TSE 2025 | D7: D04 | E7: Include for abstract screening | F7: T7
A8: I07 | B8: A Framework for Enhancing Code Security in LLMs via Hierarchical Security-Context RAG | C8: ICEE 2026 | D8: D04 | E8: Include for abstract screening | F8: T7 defense
A9: I08 | B9: Durinn: Scaling Vibe Coding Auditing | C9: IEEE BigData 2025 | D9: D05 | E9: Include for abstract screening | F9: T7 defense
A10: I09 | B10: Beyond Correctness: Measuring Hallucination Impact in AI-Assisted Development Workflows | C10: ICIETSD 2026 | D10: D05 | E10: Include for abstract screening | F10: T1? (check)
A11: I10 | B11: The Software Librarian: Python Package Insights for Copilot | C11: ICSE Companion 2025 | D11: D06 | E11: Include for abstract screening | F11: T1, T2
A12: I11 | B12: Artificially Insecure: Examining GitHub Copilot's AI-based Vulnerability Prevention System | C12: SVCC 2025 | D12: D06 | E12: Include for abstract screening | F12: T7 defense evaluation
... A43: R01 | B43: SOK: Exploring Hallucinations and Security Risks in AI-Assisted Software Development with Insights for LLM Deployment | C43: IDSTA 2025 | D43: D06 | E43: Related work (secondary study) | F43: Closest competing SoK: read and cite
A44: R02 | B44: State of the Art of the Security of Code Generated by LLMs: A Systematic Literature Review | C44: CONISOFT 2024 | D44: D06 | E44: Related work (secondary study)
A45: K01 | B45: TrojanPuzzle: Covertly Poisoning Code-Suggestion Models | C45: IEEE S&P 2024 | D45: D06 | E45: Already in corpus (P15) | F45: Gives full author list
A46: K02 | B46: Authority Is Not a String (CapScope) | C46: LMPL 2026 | D46: D08 | E46: Already in corpus (P26)
A47: K03 | B47: Asleep at the Keyboard? (CACM 2025 version) | C47: CACM 2025 | D47: D08 | E47: Already in corpus (P10)
B49: New candidates for abstract screening | E49: =COUNTIF(E2:E47,"Include for abstract screening") -> 41
B50: All other unique records were excluded at title stage (non-coding 'copilot' products, education, productivity, model-based design, general LLM security).

Sheet Recall Check
A1: Known corpus paper indexed in the database | B1: Database | C1: Retrieved by the §3 string? | D1: Likely reason if missed
A2: TrojanPuzzle (IEEE S&P 2024) | B2: IEEE Xplore | C2: Yes
A3: Asleep at the Keyboard (IEEE S&P 2022) | B3: IEEE Xplore | C3: Yes | D3: Found by D09 (E163)
A4: Asleep at the Keyboard (CACM 2025 version) | B4: ACM DL | C4: Yes
A5: CoSec (ISSTA 2024) | B5: ACM DL | C5: Yes
A6: CapScope (LMPL 2026) | B6: ACM DL | C6: Yes
A7: Do Users Write More Insecure Code with AI Assistants? (CCS 2023) | B7: ACM DL | C7: Yes | D7: Found by D10 (A32) after adding 'code assistants'
A8: SVEN (CCS 2023) | B8: ACM DL | C8: No | D8: Still missed after the D11/D12 delta runs: the abstract says 'large LMs'. Retained as a known-item addition (snowballing)
A9: Your Code Secret Belongs to Me (FSE 2024) | B9: ACM DL | C9: Yes | D9: Found by D10 (A66) after adding 'code completion'
A10: Model editing for secure code (ISSTA 2026) | B10: ACM DL | C10: No | D10: Still missed by D10-D12; ISSTA 2026 proceedings may not be fully indexed yet. Retained as a known-item addition
A11: Recall on known papers | C11: =COUNTIF(C2:C10,"Yes")&" of "&COUNTA(C2:C10) -> 7 of 9 | D11: After the expanded re-run (D09-D12): 7 of 9. Before: 4 of 9. The two misses are added by known-item search, as recommended by Kitchenham.

Sheet Abstract Screening
A1: ID | B1: Database run | C1: Title | D1: Venue | E1: Year | F1: DOI | G1: Abstract-stage decision | H1: Reason | I1: Provisional threat | J1: Note | K1: Corpus outcome
A2: E0 | B2: D09 (IEEE) | C2: Security Vulnerabilities in AI-Generated JavaScript: A Comparative Study of Large Language Models | D2: IEEE CSR | E2: 2025 | F2: 10.1109/CSR64739.2025.11130176 | G2: Include | H2: Measurement of insecure generated code | I2: T7 | K2: T7 aggregate (scoping rule not met)
A3: E1 | B3: D09 (IEEE) | C3: Security and Quality in LLM-Generated Code: A Multi-Language, Multi-Model Analysis | D3: IEEE TDSC | E3: 2026 | F3: 10.1109/TDSC.2026.3672745 | G3: Include | H3: Measurement of insecure generated code | I3: T7 | J3: E461 is a magazine summary of this paper | K3: Coded (primary study)
A4: E2 | B4: D09 (IEEE) | C4: Poisoned ChatGPT Finds Work for Idle Hands: Exploring Developers' Coding Practices with Insecure Suggestions from Poisoned AI Models | D4: IEEE S&P | E4: 2024 | F4: 10.1109/SP54263.2024.00046 | G4: Include | H4: User study of poisoned code assistants | I4: T8 | K4: Coded (primary study)
A5: E4 | B5: D09 (IEEE) | C5: Exploring the Security Landscape of AI Generated Code: A Comprehensive Study | D5: QPAIN | E5: 2026 | F5: 10.1109/QPAIN69676.2026.11546237 | G5: Include | H5: Abstract truncated in database; kept as T7 measurement | I5: T7 | J5: Resolved from full abstract | K5: T7 aggregate (scoping rule not met)
A6: E5 | B6: D09 (IEEE) | C6: Navigating (in)Security of AI-Generated Code | D6: IEEE CSR | E6: 2024 | F6: 10.1109/CSR61664.2024.10679468 | G6: Include | H6: Measurement of insecure generated code | I6: T7 | K6: T7 aggregate (scoping rule not met)
A7: E6 | B7: D09 (IEEE) | C7: CWEval: Outcome-driven Evaluation on Functionality and Security of LLM Code Generation | D7: LLM4Code @ ICSE | E7: 2025 | F7: 10.1109/LLM4Code66737.2025.00009 | G7: Include | H7: Security benchmark | I7: T7 | K7: Coded (primary study)
A8: E7 | B8: D09 (IEEE) | C8: Research on Security Vulnerability Patterns of Code Generated by Large Language Models | D8: ECIS | E8: 2026 | F8: 10.1109/ECIS69634.2026.11604380 | G8: Related work (secondary study) | H8: Abstract describes a review that summarizes methods and tools | I8: T7 | K8: Related work (secondary study)
A9: E8 | B9: D09 (IEEE) | C9: Comparative Analysis of Security Vulnerabilities in AI-Generated Versus Human-Written Python Code | D9: SIST | E9: 2026 | F9: 10.1109/SIST61674.2026.11596372 | G9: Include | H9: Measurement of insecure generated code | I9: T7 | K9: T7 aggregate (scoping rule not met)
A10: E9 | B10: D09 (IEEE) | C10: Assessing the Security of GitHub Copilot's Generated Code - A Targeted Replication Study | D10: SANER | E10: 2024 | F10: 10.1109/SANER60148.2024.00051 | G10: Include | H10: Replication of Pearce et al. | I10: T7 | K10: T7 aggregate (scoping rule not met)
A11: E10 | B11: D09 (IEEE) | C11: Poisoning Programs by Un-Repairing Code: Security Concerns of AI-generated Code | D11: ISSRE Workshops | E11: 2023 | F11: 10.1109/ISSREW60843.2023.00060 | G11: Include | H11: Training-data poisoning attack | I11: T8 | K11: Coded (primary study)
A12: E11 | B12: D09 (IEEE) | C12: Security-Related Code Hallucinations in Large Language Models: A Systematic Literature Review | D12: ISSATK | E12: 2026 | F12: 10.1109/ISSATK69667.2026.11566869 | G12: Related work (secondary study) | H12: Secondary study | I12: T1, T7 | K12: Related work (secondary study)
A13: E13 | B13: D09 (IEEE) | C13: PwnPilot: Reflections on Trusting Trust in the Age of Large Language Models and AI Code Assistants | D13: CSCE | E13: 2023 | F13: 10.1109/CSCE60160.2023.00396 | G13: Related work (secondary study) | H13: Targeted survey 2019-2023 | I13: - | K13: Related work (secondary study)
A14: E15 | B14: D09 (IEEE) | C14: Vulnerability Handling of AI-Generated Code - Existing Solutions and Open Challenges | D14: AIxSET | E14: 2024 | F14: 10.1109/AIxSET62544.2024.00026 | G14: Related work (secondary study) | H14: Overview of existing solutions | I14: T7 | K14: Related work (secondary study)
A15: E16 | B15: D09 (IEEE) | C15: Securing LLM-Generated Code with Iterative Static Analysis and LLM Review | D15: CIACON | E15: 2026 | F15: 10.1109/CIACON70148.2026.11688692 | G15: Include | H15: Defense (generation-time repair loop) | I15: T7 | K15: T7 aggregate (scoping rule not met)
A16: E17 | B16: D09 (IEEE) | C16: A Disguised Wolf Is More Harmful Than a Toothless Tiger: Adaptive and Malicious Code Injection Backdoor Attack Leveraging User Behavior as Triggers | D16: IEEE TIFS | E16: 2025 | F16: 10.1109/TIFS.2025.3620146 | G16: Include | H16: Backdoor attack on code LLMs | I16: T8 | K16: Coded (primary study)
A17: E18 | B17: D09 (IEEE) | C17: Artificially Insecure: Examining GitHub Copilot's AI-based Vulnerability Prevention System | D17: SVCC | E17: 2025 | F17: 10.1109/SVCC65277.2025.11133629 | G17: Include | H17: Evaluates a deployed defense | I17: T7 | K17: T7 aggregate (scoping rule not met)
... A19: E21 | B19: D09 (IEEE) | C19: How Developers Respond to Insecure AI Code Suggestions under Poisoning Attacks: An Empirical Study of Interface-Level Countermeasures | D19: IEEE TSE | E19: 2026 | F19: 10.1109/TSE.2026.3731966 | G19: Include | H19: User study; interface defenses against poisoning | I19: T8 | K19: Coded (primary study)
A20: E22 | B20: D09 (IEEE) | C20: HalluGuard: A Multi-Signal Detection Framework for Hallucinations in LLM-Generated Code | D20: AIIoT | E20: 2026 | F20: 10.1109/AIIoT68874.2026.11569641 | G20: Include | H20: Full abstract: self-referential SDK imports in 16% of Claude samples; security-relevant | I20: T1, T7 | J20: Resolved from full abstract | K20: Coded (primary study)
A21: E25 | B21: D09 (IEEE) | C21: Static Analysis of Vulnerabilities That AI-Based Code Assistants May Introduce | D21: ISADES | E21: 2026 | F21: 10.1109/ISADES69945.2026.11608062 | G21: Include | H21: Measurement (vibe-coded web apps) | I21: T7 | K21: T7 aggregate (scoping rule not met)
A22: E26 | B22: D09 (IEEE) | C22: Security Degradation in Iterative AI Code Generation: A Systematic Analysis of the Paradox | D22: IEEE ISTAS | E22: 2025 | F22: 10.1109/ISTAS65609.2025.11269659 | G22: Include | H22: Measurement across feedback iterations | I22: T7 | K22: T7 aggregate (scoping rule not met)
A23: E30 | B23: D09 (IEEE) | C23: Securing AI Code Generation Through Automated Pattern-Based Patching | D23: DSN Workshops | E23: 2025 | F23: 10.1109/DSN-W65791.2025.00077 | G23: Include | H23: Defense (post-generation patching) | I23: T7 | K23: T7 aggregate (scoping rule not met)
A24: E31 | B24: D09 (IEEE) | C24: From Theory to Practice: Code Generation Using LLMs for CAPEC and CWE Frameworks | D24: LLM4Code @ ICSE | E24: 2025 | F24: 10.1109/LLM4Code66737.2025.00022 | G24: Exclude | H24: LLM used as a security tool; no threat to or from the assistant | I24: - | J24: Generates vulnerability datasets | K24: Exclude
A25: E32 | B25: D09 (IEEE) | C25: Human-Written vs. AI-Generated Code: A Large-Scale Study of Defects, Vulnerabilities, and Complexity | D25: ISSRE | E25: 2025 | F25: 10.1109/ISSRE66568.2025.00035 | G25: Include | H25: Measurement | I25: T7 | K25: T7 aggregate (scoping rule not met)
A26: E33 | B26: D09 (IEEE) | C26: Cross-Cutting Security Analysis of LLM-Generated Code via Metamorphic Testing and Association Rule Mining | D26: IEEE IRI | E26: 2026 | F26: 10.1109/IRI69576.2026.00034 | G26: Include | H26: Detection method for generated code | I26: T7 | K26: T7 aggregate (scoping rule not met)
A27: E37 | B27: D09 (IEEE) | C27: Quality Assurance for AI-Generated Code: A Framework for Validating LLM-Produced Software in Production Environments | D27: ICICI | E27: 2026 | F27: 10.1109/ICICI68773.2026.11580904 | G27: Include | H27: Full abstract: multi-stage validation incl. vulnerability detection | I27: T7 | J27: Resolved from full abstract | K27: T7 aggregate (scoping rule not met)
A28: E38 | B28: D09 (IEEE) | C28: The Impact of Security Mindset on the Use of AI Assistants in Computing Education | D28: IEEE Trans. Education | E28: 2025 | F28: 10.1109/TE.2025.3610340 | G28: Include | H28: User study of security outcomes | I28: T7 | K28: T7 aggregate (scoping rule not met)
A29: E40 | B29: D09 (IEEE) | C29: Deploy, but verify: Analysing LLM Generated Code Safety | D29: Euromicro PDP | E29: 2025 | F29: 10.1109/PDP66500.2025.00011 | G29: Include | H29: Measurement | I29: T7 | K29: T7 aggregate (scoping rule not met)
A30: E41 | B30: D09 (IEEE) | C30: Cracks in The Stack: Hidden Vulnerabilities and Licensing Risks in LLM Pre-Training Datasets | D30: LLM4Code @ ICSE | E30: 2025 | F30: 10.1109/LLM4Code66737.2025.00018 | G30: Include | H30: Vulnerable code in pre-training data | I30: T8 | K30: Coded (primary study)
A31: E43 | B31: D09 (IEEE) | C31: Exploring the Security Threats of Knowledge Base Poisoning in Retrieval-Augmented Code Generation | D31: IEEE TSE | E31: 2026 | F31: 10.1109/TSE.2026.3689066 | G31: Include | H31: Retrieval-corpus poisoning attack | I31: T8 | K31: Coded (primary study)
A32: E44 | B32: D09 (IEEE) | C32: LLMSecEval: A Dataset of Natural Language Prompts for Security Evaluations | D32: MSR | E32: 2023 | F32: 10.1109/MSR59073.2023.00084 | G32: Include | H32: Security benchmark | I32: T7 | K32: Coded (primary study)
A33: E45 | B33: D09 (IEEE) | C33: Exploring Security Risks and Mitigation Strategies in AI Code Helpers | D33: LISAT | E33: 2024 | F33: 10.1109/LISAT63094.2024.10807934 | G33: Include | H33: Secret/credential disclosure | I33: T6 | K33: Coded (primary study)
A34: E47 | B34: D09 (IEEE) | C34: Prompting for Security: A Cross-Model Evaluation of Code Generation in LLMs | D34: UBMK | E34: 2025 | F34: 10.1109/UBMK67458.2025.11207030 | G34: Include | H34: Measurement of prompting defenses | I34: T7 | K34: T7 aggregate (scoping rule not met)
A35: E48 | B35: D09 (IEEE) | C35: Static Analysis as a Feedback Loop: Enhancing LLM-Generated Code Beyond Correctness | D35: SCAM | E35: 2025 | F35: 10.1109/SCAM67354.2025.00017 | G35: Include | H35: Defense (static-analysis feedback) | I35: T7 | K35: T7 aggregate (scoping rule not met)
A36: E50 | B36: D09 (IEEE) | C36: Securing AI Code Generation - A Prompt Rectification Approach for Mitigating Cyber Risks | D36: IEEE TrustCom | E36: 2025 | F36: 10.1109/Trustcom66490.2025.00106 | G36: Include | H36: Defense (prompt rectification) | I36: T7 | K36: T7 aggregate (scoping rule not met)
A37: E53 | B37: D09 (IEEE) | C37: TrustGuard: Enforcing Trust in AI-Generated Software Supply Chains | D37: IEEE ISI | E37: 2026 | F37: 10.1109/ISI69914.2026.11685843 | G37: Include | H37: Provenance defense for AI-generated artifacts | I37: T2, T7 | J37: Directly on topic: read in full | K37: Coded (primary study)
A38: E54 | B38: D09 (IEEE) | C38: Evaluating Static Security Gates and Learned Detectors on LLM-Generated Code in CI/CD Pipelines | D38: IEEE Access | E38: 2026 | F38: 10.1109/ACCESS.2026.3743230 | G38: Include | H38: Defense evaluation at CI/CD | I38: T7 | K38: Coded (primary study)
A39: E55 | B39: D09 (IEEE) | C39: Security Analysis of LLM-Generated Web API Backends | D39: IEEE Access | E39: 2026 | F39: 10.1109/ACCESS.2026.3727682 | G39: Include | H39: Measurement | I39: T7 | K39: T7 aggregate (scoping rule not met)
A40: E56 | B40: D09 (IEEE) | C40: Retrieve, Refine, or Both? Using Task-Specific Guidelines for Secure Python Code Generation | D40: ICSME | E40: 2025 | F40: 10.1109/ICSME64153.2025.00041 | G40: Include | H40: Defense (guideline retrieval) | I40: T7 | K40: T7 aggregate (scoping rule not met)
A41: E60 | B41: D09 (IEEE) | C41: SCCA: A Multi-Agent Code Security Analysis Framework for AI-Assisted Code Generation | D41: IEEE MASS | E41: 2025 | F41: 10.1109/MASS66014.2025.00089 | G41: Include | H41: Defense (multi-agent analysis) | I41: T7 | K41: T7 aggregate (scoping rule not met)
...

Sheet Screening
A1: Record ID | B1: Title | C1: Authors (as retrieved) | D1: Year | E1: Venue / status | F1: Identifier / URL | G1: Found by | H1: Record type | I1: Decision | J1: Reason | K1: Threat class (provisional) | L1: Verification note
A2: P01 | B2: We Have a Package for You! A Comprehensive Analysis of Package Hallucinations by Code Generating LLMs | C2: Spracklen, Wijewickrama, Sakib, Maiti, Viswanath, Jadliwala | D2: 2025 | E2: USENIX Security 2025 | F2: https://www.usenix.org/conference/usenixsecurity25/presentation/spracklen | G2: Q01 | H2: Primary (academic) | I2: Include | J2: Measures package hallucination by code LLMs and evaluates mitigations | K2: T1; defense (S2) | L2: Venue confirmed on usenix.org
A3: P02 | B3: The Range Shrinks, the Threat Remains: Re-evaluating LLM Package Hallucinations on the 2026 Frontier-Model Cohort | C3: Churilov | D3: 2026 | E3: arXiv preprint (not peer reviewed) | F3: arXiv:2605.17062 | G3: Q14 | H3: Primary (academic) | I3: Include | J3: Replicates P01 on five 2026 frontier models | K3: T1 | L3: arXiv ID seen in index; not peer reviewed
A4: P03 | B4: Correct Code, Vulnerable Dependencies: A Large Scale Measurement Study of LLM-Specified Library Versions | C4: Wang, Wu, Ling, Luo, Zhao | D4: 2026 | E4: arXiv preprint | F4: arXiv:2605.06279 | G4: Q17 | H4: Primary (academic) | I4: Include | J4: Measures CVE exposure of library versions chosen by LLMs | K4: T2 | L4: Authors from alphaXiv/SOTAVerified listing
A5: P04 | B5: Investigating Security Implications of Automatically Generated Code on the Software Supply Chain | C5: Li, Gao | D5: 2025 | E5: arXiv preprint (venue not confirmed) | F5: arXiv:2509.20277 | G5: Q20 | H5: Primary (academic) | I5: Include | J5: Supply-chain threats in LLM-generated code and CI configs; proposes SSCGuard | K5: T1, T2; defense (S2/S3) | L5: Check whether published at a venue
A6: P05 | B6: QueryIPI: Query-agnostic Indirect Prompt Injection on Coding Agents | C6: Xie, Liu, Luo, Zhang, Zhang, Li, Chen, Wang, She | D6: 2025 | E6: arXiv preprint | F6: arXiv:2510.23675 | G6: Q02 | H6: Primary (academic) | I6: Include | J6: Malicious tool descriptions hijack IDE coding agents | K6: T5, T3 | L6: arXiv abstract page retrieved
A7: P06 | B7: SkillJect: Automating Stealthy Skill-Based Prompt Injection for Coding Agents with Trace-Driven Closed-Loop Refinement | C7: Jia et al. (8 authors) | D7: 2026 | E7: arXiv preprint | F7: arXiv:2602.14211 | G7: Q02 | H7: Primary (academic) | I7: Include | J7: Poisoned agent skills inject coding agents | K7: T5, T3 | L7: Full author list to copy from arXiv
A8: P07 | B8: RepoGuardBench: Repository-Borne Prompt Injection Attacks and Lightweight Defenses for Local Coding Agents | C8: Li, D. (per Lacuna listing; confirm on OpenReview) | D8: 2026 | E8: DL4C workshop at ICML 2026 | F8: https://icml.cc/virtual/2026/82802 | G8: prior scoping | H8: Primary (academic) | I8: Include | J8: Benchmark of repository-borne injection and defenses for coding agents | K8: T3; defense (TB1/TB2) | L8: Venue corrected 27 Oct: workshop, not main ICML. Confirm author list on OpenReview
A9: P08 | B9: IssueTrojanBench: Benchmarking AI Coding Agents Against Malicious Issue Requests | C9: (arXiv page rate-limited; add authors) | D9: 2026 | E9: arXiv preprint | F9: arXiv:2607.20759 | G9: Q10 + verification search | H9: Primary (academic) | I9: Include | J9: Issue-borne injection against coding agents: 696 variants, 6 agent-model configs, 4,176 runs, 66.5% unsafe-action rate | K9: T4, T2 | L9: arXiv ID confirmed 27 Oct; figures from promptfoo catalog entry; read full text
A10: P09 | B10: MCPTox: A Benchmark for Tool Poisoning on Real-World MCP Servers | C10: Wang Z. et al. | D10: 2026 | E10: AAAI 2026 | F10: https://ojs.aaai.org/index.php/AAAI/article/view/40895 ; arXiv:2508.14925 | G10: Q06 | H10: Primary (academic) | I10: Include | J10: Tool poisoning through third-party MCP servers, a component coding agents install; general agents, borderline | K10: T5 | L10: Borderline: not coding-specific. Test count differs between sources (1,348 vs 1,497); check final version
A11: P10 | B11: Asleep at the Keyboard? Assessing the Security of GitHub Copilot's Code Contributions | C11: Pearce, Ahmad, Tan, Dolan-Gavitt, Karri | D11: 2022 | E11: IEEE S&P 2022 | F11: arXiv:2108.09293 | G11: Q03 | H11: Primary (academic) | I11: Include | J11: Security of Copilot completions on CWE scenarios | K11: T7 | L11: Venue from memory; confirm on IEEE Xplore
A12: P11 | B12: Do Users Write More Insecure Code with AI Assistants? | C12: Perry, Srivastava, Kumar, Boneh | D12: 2023 | E12: ACM CCS 2023 | F12: doi:10.1145/3576915.3623157 ; arXiv:2211.03622 | G12: Q16 | H12: Primary (academic) | I12: Include | J12: User study: AI assistance and code security | K12: T7 | L12: DOI seen in retrieved citation
A13: P12 | B13: Security Weaknesses of Copilot-Generated Code in GitHub Projects: An Empirical Study | C13: Fu, Liang, Tahir, Li, Shahin, Yu, Chen | D13: 2023 | E13: ACM TOSEM | F13: arXiv:2310.02059 | G13: Q03 | H13: Primary (academic) | I13: Include | J13: Security weaknesses in AI-generated code found in public GitHub projects | K13: T7 | L13: Confirmed on arXiv v4: 733 snippets, 200 (27.3%) with weaknesses
... A19: P18 | B19: DeepGuard: Secure Code Generation via Multi-Layer Semantic Aggregation | C19: Huang, Liu, Wu, Yin, Li, Bi, Mu, Zhang, Yan | D19: 2026 | E19: ACL 2026 | F19: 2026.acl-long.907 ; arXiv:2604.09089 | G19: Q11 | H19: Primary (academic) | I19: Include | J19: Secure code generation defense | K19: Defense (S2) for T7 | L19: ACL Anthology ID seen
A20: P19 | B20: CoSec: On-the-Fly Security Hardening of Code LLMs via Supervised Co-decoding | C20: Li, Yan, Zhang, Liu, Liu, Zhang, Chen, Lo | D20: 2024 | E20: ISSTA 2024 | F20: doi:10.1145/3650212.3680371 | G20: Q11; D10 | H20: Primary (academic) | I20: Include | J20: Decode-time security hardening; venue and authors confirmed from the ACM record (2026-10-27) | K20: Defense (S2) for T7
A21: P20 | B21: Constrained Decoding for Secure Code Generation | C21: Fu, Baker, Ding, Chen | D21: 2024 | E21: arXiv preprint | F21: arXiv:2405.00218 | G21: Q11 | H21: Primary (academic) | I21: Include | J21: Secure-and-correct decoding defense and evaluation | K21: Defense (S2) for T7 | L21: Authors confirmed from arXiv PDF; venue not stated
A22: P21 | B22: Understanding and Improving Model Editing for Secure Code Generation | C22: Sun, Zhang, Chen, Yang, Tan, Lo | D22: 2026 | E22: Proc. ACM Softw. Eng. (ISSTA 2026), doi:10.1145/3832254 | F22: arXiv:2608.06848 | G22: Q11 | H22: Primary (academic) | I22: Include | J22: Model editing as code-security hardening | K22: Defense (S2) for T7 | L22: Confirmed from arXiv PDF
A23: P22 | B23: Is Vibe Coding Safe? Benchmarking Vulnerability of Agent-Generated Code in Real-World Tasks (SusVibes) | C23: Zhao et al. | D23: 2026 | E23: ICML 2026 (PMLR v306) | F23: https://proceedings.mlr.press/v306/zhao26ax.html | G23: Q15 | H23: Primary (academic) | I23: Include | J23: Security of code produced by coding agents on real tasks | K23: T7 | L23: Proceedings page retrieved
A24: P23 | B24: Understanding the (In)Security of Vibe-Coded Applications | C24: Deng, Fan, Meng | D24: 2026 | E24: arXiv preprint | F24: arXiv:2606.23130 | G24: Q15 | H24: Primary (academic) | I24: Include | J24: Vulnerabilities in deployed vibe-coded apps and their causes | K24: T7, T6 | L24: Confirmed on arXiv: 1,471 vulnerabilities in 200 audited apps (from 10,517); 180 of 200 (90%) with at least one
A25: P24 | B25: Insights into Security-Related AI-Generated Pull Requests | C25: Rabbi, Turzo, Champa, Zibran | D25: 2026 | E25: EASE 2026 | F25: arXiv:2604.19965 | G25: Q18 | H25: Primary (academic) | I25: Include | J25: Security weaknesses and review outcomes of agent-authored PRs | K25: T7 (S5 review) | L25: Confirmed: 33,596 AI PRs, 675 security-related
A26: P25 | B26: SABER: Benchmarking Operational Safety of LLM Coding Agents in Stateful Project Workspaces | C26: Hu, Tang, Wang, Zhao, Zhang, Qing, Yao, Huang, Zhang, Ji | D26: 2026 | E26: arXiv preprint | F26: arXiv:2606.01317 | G26: Q08 | H26: Primary (academic) | I26: Include | J26: Coding-agent safety incl. instructions embedded in project artifacts | K26: T3; unsafe actions (A0) | L26: Confirmed from arXiv PDF
A27: P26 | B27: Authority Is Not a String: A Capability-Scoped Harness for Prompt-Injection-Resistant Coding Agents (CapScope) | C27: Bouras, Dai, Mechtaev | D27: 2026 | E27: LMPL 2026 workshop (ACM SIGPLAN) | F27: arXiv:2609.08371 | G27: Q22 | H27: Primary (academic) | I27: Include | J27: Capability-based tool authorization for coding agents | K27: Defense (TB2) for T3 | L27: Confirmed from arXiv PDF
A28: P27 | B28: Pincer: Resource Authorization for Agents using a Digital Twin | C28: Rathee, Stepanov, Madabhavi, Zhu, Popa, Stoica | D28: 2026 | E28: arXiv preprint | F28: arXiv:2610.02569 | G28: Q22 | H28: Primary (academic) | I28: Include | J28: Resource-layer authorization for coding agents (Claude, Codex) | K28: Defense (TB2) | L28: Confirmed from arXiv PDF; no venue stated
A29: X01 | B29: RedCode: Risky Code Execution and Generation Benchmark for Code Agents | C29: Guo et al. (8 authors) | D29: 2024 | E29: arXiv preprint | F29: arXiv:2411.07781 | G29: Q08 | H29: Primary (academic) | I29: Exclude | J29: User-directed misuse and risky execution, not a supply-chain compromise path | K29: -
A30: X02 | B30: RvB: Automating AI System Hardening via Iterative Red-Blue Games | C30: (not retrieved) | D30: 2026 | E30: arXiv preprint | F30: arXiv:2601.19726 | G30: Q11 | H30: Primary (academic) | I30: Exclude | J30: General AI-system hardening; not about AI-generated code or coding agents | K30: -
A31: X03 | B31: An Empirical Study of Vulnerable Package Dependencies in LLM Repositories | C31: (not retrieved) | D31: 2025 | E31: arXiv preprint | F31: arXiv:2508.21417 | G31: Q20 | H31: Primary (academic) | I31: Exclude | J31: Exclusion (iii): dependencies of LLM frameworks, not coding-agent pipeline | K31: -
A32: X04 | B32: Demystifying LLM Supply Chain Vulnerabilities in the Wild | C32: (not retrieved) | D32: 2025 | E32: arXiv preprint | F32: arXiv:2502.12497 | G32: Q20 | H32: Primary (academic) | I32: Exclude | J32: Exclusion (iii): vulnerabilities in LLM frameworks | K32: -
A33: X05 | B33: ATBench-CodeX / AgentDoG | C33: AI45Research | D33: 2026 | E33: Dataset card | F33: https://huggingface.co/datasets/AI45Research/ATBench-CodeX | G33: Q08 | H33: Primary (academic) | I33: Exclude | J33: General agent-safety guardrail benchmark; no supply-chain focus | K33: -
A34: X06 | B34: AgentS4D; VulnGym; MTGuard; DDIPE (agent skills) | C34: (various) | D34: 2026 | E34: Seen only in an aggregator | F34: https://www.promptfoo.dev/lm-security-db/ | G34: Q08, Q10 | H34: Primary (academic) | I34: Pending verification | J34: Possibly in scope; primary sources not retrieved | K34: - | L34: Locate primaries before screening
A35: C01 | B35: StruQ: Defending Against Prompt Injection with Structured Queries | C35: Chen, Piet, Sitawarin, Wagner | D35: 2025 | E35: USENIX Security 2025 | F35: arXiv:2402.06363 | G35: Q12 | H35: Context (general LLM/agent) | I35: Exclude | J35: Exclusion (ii): general LLM defense, not evaluated on coding agents; cited as background | K35: Defense (TB1) background
A36: C02 | B36: Defeating Prompt Injections by Design (CaMeL) | C36: Debenedetti, Shumailov, Fan, Hayes, Carlini, Fabian, Kern, Shi, Terzis, Tramer | D36: 2025 | E36: arXiv preprint | F36: arXiv:2503.18813 | G36: Q13 | H36: Context (general LLM/agent) | I36: Exclude | J36: Exclusion (ii): general agents (AgentDojo); cited as background | K36: Defense (TB1-TB2) background
A37: C03 | B37: ChatInject; AttackEval | C37: (various) | D37: 2025 | E37: arXiv preprints | F37: seen on huggingface.co papers listing | G37: Q12 | H37: Context (general LLM/agent) | I37: Exclude | J37: Exclusion (ii): general prompt injection | K37: -
A38: S01 | B38: Security of Language Models for Code: A Systematic Literature Review | C38: Chen, Sun, Fang, Chen, Ge, Han, Zhang, Liu, Chen, Xu | D38: 2024 | E38: ACM TOSEM | F38: arXiv:2410.15631 | G38: Q24 | H38: Secondary study | I38: Exclude | J38: Secondary study (68 papers); related work, not primary corpus | K38: -
A39: S02 | B39: From Vulnerabilities to Remediation: A Systematic Literature Review of LLMs in Code Security | C39: Basic, Giaretta | D39: 2024 | E39: arXiv preprint | F39: arXiv:2412.15004 | G39: Q24 | H39: Secondary study | I39: Exclude | J39: Secondary study; related work, not primary corpus | K39: -
A40: S03 | B40: Prompt Injection Attacks on Agentic Coding Assistants: A Systematic Analysis of Vulnerabilities in Skills, Tools, and Protocol Ecosystems | C40: Maloyan, Namiot | D40: 2026 | E40: arXiv preprint | F40: arXiv:2601.17548 | G40: Snowball (Phase 3): source of the '78 studies' figure cited by CSA 2026a | H40: Secondary study | I40: Exclude | J40: Secondary study (SoK of 78 sources); closest related work on T3/T5; used for backward snowballing | K40: -
A41: P28 | B41: "Your AI, My Shell": Demystifying Prompt Injection Attacks on Agentic AI Coding Editors (AIShellJack) | C41: Liu, Zhao, Lyu, Zhang, Wang, Lo | D41: 2025 | E41: arXiv preprint | F41: arXiv:2509.22040 | G41: Snowball (Phase 3) from S03 | H41: Primary (academic) | I41: Include | J41: Prompt injection via rule files and external resources in Cursor and GitHub Copilot; 314 payloads | K41: T3 | L41: Figures from a third-party abstract summary; check against the PDF
A42: P29 | B42: MCPSecBench: A Systematic Security Benchmark and Playground for Testing Model Context Protocols | C42: Yang, Wu, Chen | D42: 2025 | E42: arXiv preprint | F42: arXiv:2508.13220 | G42: Snowball (Phase 3) from S03 | H42: Primary (academic) | I42: Include | J42: MCP attack taxonomy (17 attack types, 4 surfaces) and benchmark across MCP hosts incl. Cursor | K42: T5 | L42: Figures from a third-party abstract summary; check against the PDF
A43: C04 | B43: The Attacker Moves Second: Stronger Adaptive Attacks Bypass Defenses Against LLM Jailbreaks and Prompt Injections | C43: Nasr, Carlini, Sitawarin, Schulhoff, Hayes, Ilie, Pluto, Song, Chaudhari, Shumailov, Thakurta, Xiao, Terzis, Tramer | D43: 2026 | E43: USENIX Security 2026 | F43: arXiv:2510.09023 | G43: Snowball (Phase 3) from S03 | H43: Context (general LLM/agent) | I43: Exclude | J43: Exclusion (ii): general LLM defenses; cited as background on adaptive attacks | K43: -
A44: G01 | B44: README Injection: Repository Files Hijacking AI Coding Assistants | C44: Cloud Security Alliance | D44: 2026 | E44: Research note, Mar 2026 | F44: https://labs.cloudsecurityalliance.org/research/csa-research-note-readme-instruction-injection-ai-coding-age/ | G44: prior scoping | H44: Grey literature | I44: Include | J44: Incident and prevalence evidence for repository injection | K44: T3
A45: G02 | B45: Vibe Coding's Security Debt: The AI-Generated CVE Surge | C45: Cloud Security Alliance | D45: 2026 | E45: Research note, Apr 2026 | F45: https://labs.cloudsecurityalliance.org/research/csa-research-note-ai-generated-code-vulnerability-surge-2026/ | G45: prior scoping | H45: Grey literature | I45: Include | J45: Prevalence evidence (CVEs, leaked secrets) | K45: T7, T6 | L45: Underlying Veracode / Georgia Tech / Escape.tech sources not retrieved directly
...

Sheet Coding
A1: ID | B1: Short name | C1: Type | D1: Peer reviewed | E1: Primary threat (coder 1) | F1: T1 | G1: T2 | H1: T3 | I1: T4 | J1: T5 | K1: T6 | L1: T7 | M1: T8 | N1: Attack | O1: Measurement | P1: Benchmark | Q1: Defense | R1: User study | S1: Attacker | T1: SDLC stages | U1: Max autonomy (L) | V1: Evaluated on agent | W1: Defense enforcement point | X1: Defense maturity | Y1: Utility measured | Z1: Adaptive attacker | AA1: Artifacts released | AB1: Evidence basis | AC1: Needs full-text check
A2: P01 | B2: Spracklen et al. 2025 | C2: Academic | D2: Y | E2: T1 | F2: 1 | G2: 0 | H2: 0 | I2: 0 | J2: 0 | K2: 0 | L2: 0 | M2: 0 | N2: 0 | O2: 1 | P2: 0 | Q2: 1 | R2: 0 | S2: A1 (+A0) | T2: S2,S3 | U2: 2 | V2: N | W2: S2 generation | X2: E1 | Y2: Y | Z2: NS | AA2: Y | AB2: Abstract + USENIX page; poster | AC2: Y
A3: P02 | B3: Churilov 2026 | C3: Academic | D3: N | E3: T1 | F3: 1 | G3: 0 | H3: 0 | I3: 0 | J3: 0 | K3: 0 | L3: 0 | M3: 0 | N3: 0 | O3: 1 | P3: 0 | Q3: 0 | R3: 0 | S3: A1 | T3: S2,S3 | U3: 2 | V3: N | W3: - | X3: - | Y3: NS | Z3: NS | AA3: NS | AB3: Abstract + news coverage | AC3: Y
A4: P03 | B4: Wang C. et al. 2026 | C4: Academic | D4: N | E4: T2 | F4: 0 | G4: 1 | H4: 0 | I4: 0 | J4: 0 | K4: 0 | L4: 0 | M4: 0 | N4: 0 | O4: 1 | P4: 0 | Q4: 1 | R4: 0 | S4: A0 | T4: S2,S3 | U4: 2 | V4: N | W4: S3 dependency intake | X4: E1 | Y4: Y | Z4: NS | AA4: Y | AB4: Abstract (PinTrace released on GitHub) | AC4: Y
A5: P04 | B5: Li & Gao 2025 | C5: Academic | D5: N | E5: T1 | F5: 1 | G5: 1 | H5: 0 | I5: 0 | J5: 0 | K5: 0 | L5: 0 | M5: 0 | N5: 0 | O5: 1 | P5: 0 | Q5: 1 | R5: 0 | S5: A1 (+A0) | T5: S2,S3,S5 | U5: 2 | V5: N | W5: S2 generation + S3 middleware | X5: E1 | Y5: NS | Z5: NS | AA5: NS | AB5: Abstract + arXiv HTML intro | AC5: Y
A6: P05 | B6: Xie et al. 2025 (QueryIPI) | C6: Academic | D6: N | E6: T5 | F6: 0 | G6: 0 | H6: 1 | I6: 0 | J6: 1 | K6: 0 | L6: 0 | M6: 0 | N6: 1 | O6: 0 | P6: 0 | Q6: 0 | R6: 0 | S6: A3 | T6: S1,S2 | U6: 4 | V6: Y | W6: - | X6: - | Y6: NS | Z6: Y | AA6: NS | AB6: Abstract (iterative attack optimization; 5 simulated agents + transfer) | AC6: Y
A7: P06 | B7: Jia et al. 2026 (SkillJect) | C7: Academic | D7: N | E7: T5 | F7: 0 | G7: 0 | H7: 1 | I7: 0 | J7: 1 | K7: 0 | L7: 0 | M7: 0 | N7: 1 | O7: 0 | P7: 0 | Q7: 0 | R7: 0 | S7: A3 | T7: S1,S2,S4 | U7: 4 | V7: Y | W7: - | X7: - | Y7: NS | Z7: Y | AA7: NS | AB7: Abstract (closed-loop attack refinement) | AC7: Y
A8: P07 | B8: RepoGuardBench 2026 (DL4C@ICML) | C8: Academic | D8: Y | E8: T3 | F8: 0 | G8: 0 | H8: 1 | I8: 0 | J8: 0 | K8: 0 | L8: 0 | M8: 0 | N8: 0 | O8: 0 | P8: 1 | Q8: 1 | R8: 0 | S8: A2 | T8: S2,S4 | U8: 4 | V8: Y | W8: TB1 context + TB2 action | X8: E2 | Y8: Y | Z8: N | AA8: NS | AB8: Abstract (2,340 runs; 8 defenses) | AC8: Y
A9: P08 | B9: IssueTrojanBench 2026 | C9: Academic | D9: N | E9: T4 | F9: 0 | G9: 1 | H9: 0 | I9: 1 | J9: 0 | K9: 0 | L9: 0 | M9: 0 | N9: 1 | O9: 0 | P9: 1 | Q9: 0 | R9: 0 | S9: A2 | T9: S7 | U9: 4 | V9: Y | W9: - | X9: - | Y9: NS | Z9: NS | AA9: NS | AB9: Catalog entry + arXiv listing (696 variants, 4,176 runs, 66.5%) | AC9: Y
A10: P09 | B10: Wang Z. et al. 2026 (MCPTox) | C10: Academic | D10: Y | E10: T5 | F10: 0 | G10: 0 | H10: 0 | I10: 0 | J10: 1 | K10: 0 | L10: 0 | M10: 0 | N10: 0 | O10: 0 | P10: 1 | Q10: 0 | R10: 0 | S10: A3 | T10: All | U10: 4 | V10: Y | W10: - | X10: - | Y10: NS | Z10: NS | AA10: Y | AB10: Abstract (20 general agents; benchmark released) | AC10: Y
A11: P10 | B11: Pearce et al. 2022 | C11: Academic | D11: Y | E11: T7 | F11: 0 | G11: 0 | H11: 0 | I11: 0 | J11: 0 | K11: 0 | L11: 1 | M11: 0 | N11: 0 | O11: 1 | P11: 0 | Q11: 0 | R11: 0 | S11: A0 | T11: S2 | U11: 1 | V11: N | W11: - | X11: - | Y11: NS | Z11: N | AA11: NS | AB11: arXiv PDF method section | AC11: Y
A12: P11 | B12: Perry et al. 2023 | C12: Academic | D12: Y | E12: T7 | F12: 0 | G12: 0 | H12: 0 | I12: 0 | J12: 0 | K12: 0 | L12: 1 | M12: 0 | N12: 0 | O12: 0 | P12: 0 | Q12: 0 | R12: 1 | S12: A0 | T12: S2 | U12: 2 | V12: N | W12: - | X12: - | Y12: NS | Z12: N | AA12: Y | AB12: Abstract (apparatus and data released) | AC12: N
A13: P12 | B13: Fu et al. 2023 | C13: Academic | D13: Y | E13: T7 | F13: 0 | G13: 0 | H13: 0 | I13: 0 | J13: 0 | K13: 0 | L13: 1 | M13: 0 | N13: 0 | O13: 1 | P13: 0 | Q13: 1 | R13: 0 | S13: A0 | T13: S2,S6 | U13: 2 | V13: N | W13: S5 review (LLM-based fixing) | X13: E1 | Y13: NS | Z13: N | AA13: NS | AB13: TOSEM abstract (733 snippets; 29.5% Python, 24.2% JavaScript; 43 CWEs; Copilot Chat fixed up to 55.5%) | AC13: N
... A97: E53 | B97: TrustGuard provenance (ISI 2026) | C97: Academic | D97: Y | E97: T2 | F97: 0 | G97: 1 | H97: 0 | I97: 0 | J97: 0 | K97: 0 | L97: 1 | M97: 0 | N97: 0 | O97: 0 | P97: 0 | Q97: 1 | R97: 0 | S97: A0 | T97: S6 | U97: 4 | V97: N | W97: S6 provenance attestation | X97: E1 | Y97: NS | Z97: NS | AA97: NS | AB97: Database abstract (IEEE/ACM record, read 2026-10-27) | AC97: Y
A99: Legend: T1-T8 and contribution columns are 1/0 flags. Rows with letter IDs E/A/N/M come from the database re-run (D09-D12) and are coded from full database abstracts only. NS = not stated in the text retrieved. Maturity E0-E3 per paper §3; only for papers that propose or evaluate a defense. All codes are single-coder and provisional.

Sheet Double coding
A1: ID | B1: Short name | C1: Coder 1 primary threat (original) | D1: Claude blind re-code (intra-coder check; NOT independent) | E1: Agree (C vs D) | F1: Human coder 2 primary threat (ENTER; independent) | G1: Agree (C vs F)
A2: A102 | B2: Differential privacy for IDE autocomplete (IDE 2026) | C2: T6 | D2: T6 | E2: =IF(D2="","",IF(C2=D2,1,0)) -> 1 | F2: T6 | G2: =IF(F2="","",IF(C2=F2,1,0)) -> 1
A3: A14 | B3: Red-teaming coding agents via tool invocation (ISSTA 2026) | C3: T5 | D3: T5 | E3: =IF(D3="","",IF(C3=D3,1,0)) -> 1 | F3: T5 | G3: =IF(F3="","",IF(C3=F3,1,0)) -> 1
A4: A143 | B4: Security & privacy in LLM-native IDEs (ASE 2026) | C4: T6 | D4: T6 | E4: =IF(D4="","",IF(C4=D4,1,0)) -> 1 | F4: T6 | G4: =IF(F4="","",IF(C4=F4,1,0)) -> 1
A5: A24 | B5: AIALIB threat library (ASE 2026) | C5: T7 | D5: T7 | E5: =IF(D5="","",IF(C5=D5,1,0)) -> 1 | F5: T7 | G5: =IF(F5="","",IF(C5=F5,1,0)) -> 1
A6: E142 | B6: IDE-Sanitizer (SmartNets 2026) | C6: T3 | D6: T3 | E6: =IF(D6="","",IF(C6=D6,1,0)) -> 1 | F6: T3 | G6: =IF(F6="","",IF(C6=F6,1,0)) -> 1
A7: E20 | B7: CodeLMSec (SaTML 2024) | C7: T7 | D7: T7 | E7: =IF(D7="","",IF(C7=D7,1,0)) -> 1 | F7: T7 | G7: =IF(F7="","",IF(C7=F7,1,0)) -> 1
A8: E258 | B8: Occlusion-based trojan trigger finding (CAIN 2025) | C8: T8 | D8: T8 | E8: =IF(D8="","",IF(C8=D8,1,0)) -> 1 | F8: T8 | G8: =IF(F8="","",IF(C8=F8,1,0)) -> 1
A9: E373 | B9: Codebreaker extraction attacks (S&P 2025) | C9: T6 | D9: T6 | E9: =IF(D9="","",IF(C9=D9,1,0)) -> 1 | F9: T6 | G9: =IF(F9="","",IF(C9=F9,1,0)) -> 1
A10: E54 | B10: Security gates in CI/CD (IEEE Access 2026) | C10: T7 | D10: T7 | E10: =IF(D10="","",IF(C10=D10,1,0)) -> 1 | F10: T7 | G10: =IF(F10="","",IF(C10=F10,1,0)) -> 1
A11: E68 | B11: ShadowCode external prompt injection (TDSC 2026) | C11: T3 | D11: T3 | E11: =IF(D11="","",IF(C11=D11,1,0)) -> 1 | F11: T3 | G11: =IF(F11="","",IF(C11=F11,1,0)) -> 1
A12: E76 | B12: STRIDE analysis of AI coding tools (VCC 2023) | C12: T3 | D12: T6 | E12: =IF(D12="","",IF(C12=D12,1,0)) -> 0 | F12: T6 | G12: =IF(F12="","",IF(C12=F12,1,0)) -> 0
A13: N1 | B13: DeCE backdoor defense (TOSEM 2026) | C13: T8 | D13: T8 | E13: =IF(D13="","",IF(C13=D13,1,0)) -> 1 | F13: T8 | G13: =IF(F13="","",IF(C13=F13,1,0)) -> 1
... A18: P16 | B18: Yan et al. 2024 (CodeBreaker) | C18: T8 | D18: T8 | E18: =IF(D18="","",IF(C18=D18,1,0)) -> 1 | F18: T8 | G18: =IF(F18="","",IF(C18=F18,1,0)) -> 1
A20: Category | B20: Coder 1 count | C20: Claude re-code count | D20: Human coder 2 count
A21: T1 | B21: =COUNTIF($C$2:$C$18,A21) -> 1 | C21: =COUNTIF($D$2:$D$18,A21) -> 1 | D21: =COUNTIF($F$2:$F$18,A21) -> 1
A22: T2 | B22: =COUNTIF($C$2:$C$18,A22) -> 0 | C22: =COUNTIF($D$2:$D$18,A22) -> 0 | D22: =COUNTIF($F$2:$F$18,A22) -> 0
A23: T3 | B23: =COUNTIF($C$2:$C$18,A23) -> 3 | C23: =COUNTIF($D$2:$D$18,A23) -> 2 | D23: =COUNTIF($F$2:$F$18,A23) -> 2
A24: T4 | B24: =COUNTIF($C$2:$C$18,A24) -> 0 | C24: =COUNTIF($D$2:$D$18,A24) -> 0 | D24: =COUNTIF($F$2:$F$18,A24) -> 0
A25: T5 | B25: =COUNTIF($C$2:$C$18,A25) -> 1 | C25: =COUNTIF($D$2:$D$18,A25) -> 1 | D25: =COUNTIF($F$2:$F$18,A25) -> 1
A26: T6 | B26: =COUNTIF($C$2:$C$18,A26) -> 3 | C26: =COUNTIF($D$2:$D$18,A26) -> 4 | D26: =COUNTIF($F$2:$F$18,A26) -> 4
A27: T7 | B27: =COUNTIF($C$2:$C$18,A27) -> 4 | C27: =COUNTIF($D$2:$D$18,A27) -> 4 | D27: =COUNTIF($F$2:$F$18,A27) -> 4
A28: T8 | B28: =COUNTIF($C$2:$C$18,A28) -> 5 | C28: =COUNTIF($D$2:$D$18,A28) -> 5 | D28: =COUNTIF($F$2:$F$18,A28) -> 5
A30: A. Intra-coder consistency (coder 1 vs Claude blind re-code)
A31: n coded by both | B31: =COUNTA(D2:D18) -> 17
A32: Observed agreement p_o | B32: =IF(B31=0,"",SUM(E2:E18)/B31) -> 0.94117647
A33: Expected agreement p_e | B33: =IF(B31=0,"",SUMPRODUCT(B21:B28,C21:C28)/B31^2) -> 0.21107266
A34: Cohen's kappa = (p_o - p_e)/(1 - p_e) | B34: =IF(B31<17,"enter all 17 values",IF(B33=1,1,(B32-B33)/(1-B33))) -> 0.9254386
A36: B. Inter-rater reliability (coder 1 vs independent human coder 2) - REPORT THIS ONE
A37: n coded by both | B37: =COUNTA(F2:F18) -> 17
A38: Observed agreement p_o | B38: =IF(B37=0,"",SUM(G2:G18)/B37) -> 0.94117647
A39: Expected agreement p_e | B39: =IF(B37=0,"",SUMPRODUCT(B21:B28,D21:D28)/B37^2) -> 0.21107266
A40: Cohen's kappa = (p_o - p_e)/(1 - p_e) | B40: =IF(B37<17,"enter all 17 values",IF(B39=1,1,(B38-B39)/(1-B39))) -> 0.9254386
A42: Sample: 17 of the 85 academic papers coded before Phase 3 snowballing (20%), drawn with Python random.seed(2026) and then frozen. Expected agreement uses both codings' marginal counts. Column C keeps coder 1's original code; adjudicated codes are in the Coding sheet.
A43: Block A: Claude re-coded each paper from title and full abstract without consulting column C. Claude was also coder 1, so this is intra-coder consistency, not inter-rater reliability.
A44: Block B: column F must be filled by a human who has not seen columns C-D or the Coding sheet, using HumanCoder_packet.xlsx (same abstracts and codebook). Only block B may be reported as inter-rater agreement.
